Workbook

Sheet Diagrama ER (corregido)

Sheet Invetario de Tablas
A1: Modelo Físico - Tablas resultantes del Diccionario de Datos MEJORADO
A2: INVENTARIO DE TABLAS
A3: # | B3: Tabla | C3: Descripción Tabla | D3: Observaciones
A4: 1 | B4: rol | C4: Almacena los roles de los usuarios | D4: Tabla independiente
A5: =A4+1 -> 2 | B5: tipo_usuario | C5: Clasifica los tipos de usuarios | D5: Tabla independiente
A6: =A5+1 -> 3 | B6: usuario | C6: Guarda la información principal de los usuarios | D6: Relacionada con rol y tipo_usuario
A7: =A6+1 -> 4 | B7: perfil | C7: Contiene información extendida del usuario | D7: Usa JSONB
A8: =A7+1 -> 5 | B8: publicacion | C8: Registra publicaciones de usuarios | D8: Depende de usuario
A9: =A8+1 -> 6 | B9: comentario | C9: Guarda comentarios de publicaciones | D9: Relación usuario-publicación
A10: =A9+1 -> 7 | B10: grupo_social | C10: Almacena grupos académicos o sociales | D10: Depende de usuario
A11: =A10+1 -> 8 | B11: evento | C11: Registra eventos estudiantiles | D11: Depende de usuario
A12: =A11+1 -> 9 | B12: servicio | C12: Registra servicios publicados | D12: Depende de usuario
A13: =A12+1 -> 10 | B13: producto | C13: Registra productos publicados | D13: Depende de usuario
A14: =A13+1 -> 11 | B14: grupo_usuarios | C14: Relaciona usuarios con grupos | D14: Tabla puente
A15: =A14+1 -> 12 | B15: usuario_habilidad | C15: Relaciona usuarios con habilidades | D15: Tabla puente
A16: =A15+1 -> 13
A17: =A16+1 -> 14
A18: =A17+1 -> 15
A19: =A18+1 -> 16
A20: =A19+1 -> 17
A21: =A20+1 -> 18
A22: =A21+1 -> 19
A23: =A22+1 -> 20
A24: =A23+1 -> 21
A25: =A24+1 -> 22
A26: =A25+1 -> 23
A27: =A26+1 -> 24
A28: =A27+1 -> 25

Sheet Diccionario Datos - PostgreSQL
A1: PostgreSQL - Tablas en Detalle
A3: ='Invetario de Tablas'!A4 -> 1 | B3: Tabla | C3: ='Invetario de Tablas'!B4 -> rol | G3: Descripción Tabla | K3: ='Invetario de Tablas'!C4 -> Almacena los roles de los usuarios | X3: Versión
A4: # | B4: Campo | C4: Descripción Campo | G4: Tipo Dato - PostgreSQL | K4: Tamaño | O4: Nulo | R4: PK | T4: FK | V4: UK | X4: Nota/Comentarios
A5: 1 | B5: id_rol | C5: Identificador único del rol | G5: SERIAL | O5: No | R5: S | X5: Clave primaria autoincremental
A6: 2 | B6: nombre | C6: Nombre del rol del usuario | G6: VARCHAR | K6: 50 | O6: No | V6: S | X6: Debe ser único
A7: 3 | B7: descripcion | C7: Descripción del rol | G7: TEXT | O7: Sí | X7: Información adicional del rol
A8: 4 | B8: estado | C8: Estado del rol | G8: BOOLEAN | O8: No | X8: TRUE activo / FALSE inactivo
A9: 5 | B9: fecha_creacion | C9: Fecha de creación del rol | G9: TIMESTAMP | O9: No | X9: Registro automático
A11: N
A12: NOTA: En las columnas PK, FK y UK debe colocar “S” solamente cuando aplique. En la columna “Nulo” coloque “No” en caso de que el campo debe estar valorizado
A14: ='Invetario de Tablas'!A5 -> 2 | B14: Tabla | C14: ='Invetario de Tablas'!B5 -> tipo_usuario | G14: Descripción Tabla | K14: ='Invetario de Tablas'!C5 -> Clasifica los tipos de usuarios | X14: Versión | Y14: 1
A15: # | B15: Campo | C15: Descripción Campo | G15: Tipo Dato - PostgreSQL | K15: Tamaño | O15: Nulo | R15: PK | T15: FK | V15: UK | X15: Nota/Comentarios
A16: 1 | B16: id_tipo_usuario | C16: Identificador del tipo de usuario | G16: SERIAL | O16: No | R16: S | X16: Clave primaria
A17: 2 | B17: nombre_tipo | C17: Nombre del tipo de usuario | G17: VARCHAR | K17: 50 | O17: No | V17: S | X17: Debe ser único
A18: 3 | B18: descripcion | C18: Descripción del tipo de usuario | G18: TEXT | O18: Sí | X18: Información adicional
A19: 4 | B19: nivel_acceso | C19: Nivel de permisos del usuario | G19: INTEGER | O19: No | X19: Control de acceso
A20: 5 | B20: fecha_creacion | C20: Fecha de creación | G20: TIMESTAMP | O20: No | X20: Registro automático
A22: N
A24: Puede seguir agregando tablas. Solamente tiene que copiar y pegar hacia abajo hasta que complete todas las tablas OJO - ATENCIÓN - RECUERDE COLOCAR LAS REFERENCIAS DE LAS TABLAS: NÚMERO , NOMBRE, DESCRIPCIóN
A26: 3 | B26: Tabla | C26: USUARIO | G26: Descripción Tabla | K26: Guarda la información principal de los usuarios | X26: Versión | Y26: 1
A27: # | B27: Campo | C27: Descripción Campo | G27: Tipo Dato - PostgreSQL | K27: Tamaño | O27: Nulo | R27: PK | T27: FK | V27: UK | X27: Nota/Comentarios
A28: 1 | B28: id_tipo_usuario | C28: Identificador único del usuario | G28: SERIAL | O28: No | R28: S | X28: Clave primaria
A29: 2 | B29: nombre | C29: Nombre completo del usuario | G29: VARCHAR | K29: 150 | O29: No | X29: Nombre del estudiante
A30: 3 | B30: correo | C30: Correo institucional o personal | G30: VARCHAR | K30: 100 | O30: No | V30: S | X30: Debe ser único
A31: 4 | B31: contrasena | C31: Contraseña cifrada del usuario | G31: VARCHAR | K31: 255 | O31: No | X31: Seguridad del sistema
A32: 5 | B32: fecha_registro | C32: Fecha de registro del usuario | G32: TIMESTAMP | O32: No | X32: Registro automático
B33: id_rol | C33: Rol asignado al usuario | G33: INTEGER | O33: No | T33: S | X33: Relación con tabla rol
B34: id_tipo_usuario | C34: Tipo de usuario | G34: INTEGER | O34: No | T34: S | X34: Relación con tipo_usuario
B35: estado | C35: Estado de la cuenta | G35: BOOLEAN | O35: No | X35: TRUE activo / FALSE inactivo
A36: N
A39: 4 | B39: Tabla | C39: PERFIL | G39: Descripción Tabla | K39: Contiene información extendida del usuario | X39: Versión | Y39: 1.0
A40: # | B40: Campo | C40: Descripción Campo | G40: Tipo Dato - PostgreSQL | K40: Tamaño | O40: Nulo | R40: PK | T40: FK | V40: UK | X40: Nota/Comentarios
A41: 1 | B41: id_perfil | C41: Identificador del perfil | G41: SERIAL | O41: No | R41: S | X41: Clave primaria
A42: 2 | B42: id_usuario | C42: Usuario propietario del perfil | G42: INTEGER | O42: No | T42: S | X42: Relación con usuario
A43: 3 | B43: biografia | C43: Información personal del usuario | G43: TEXT | O43: Sí | X43: Descripción del perfil
A44: 4 | B44: intereses | C44: Intereses académicos o sociales | G44: JSONB | O44: Sí | X44: Manejo de Big Data
A45: 5 | B45: habilidades | C45: Habilidades técnicas o deportivas | G45: JSONB | O45: Sí | X45: Información semiestructurada
A46: 6 | B46: foto_perfil | C46: URL de imagen del perfil | G46: VARCHAR | K46: 255 | O46: Sí | X46: Ruta de imagen
A47: 7 | B47: fecha_actualizacion | C47: Fecha de actualización | G47: TIMESTAMP | O47: No | X47: Control de cambios
A48: N
...
